<?xml version="1.0"?>
<robot xmlns:xacro="http://ros.org/wiki/xacro">
  <xacro:macro name="abb_irb4600_40_255" params="prefix">
    <xacro:include filename="$(find irb4600_description)/urdf/common_materials.xacro"/>

    <!-- link list -->
    <link name="${prefix}base_link">
      <collision name="collision">
        <geometry>
          <mesh filename="package://irb4600_description/meshes/collision/base_link.stl"/>
        </geometry>
        <xacro:material_abb_white/>
      </collision>
      <visual name="visual">
        <geometry>
          <mesh filename="package://irb4600_description/meshes/visual/base_link.dae"/>
        </geometry>
        <xacro:material_abb_white/>
        <material name="yellow">
          <color rgba="1 1 0 1"/>
        </material>
      </visual>
    </link>
    <link name="${prefix}shoulder_pan_link">
      <collision name="collision">
        <geometry>
          <mesh filename="package://irb4600_description/meshes/collision/link_1.stl"/>
        </geometry>
        <xacro:material_abb_white/>
      </collision>
      <visual name="visual">
        <geometry>
          <mesh filename="package://irb4600_description/meshes/visual/link_1.dae"/>
        </geometry>
        <xacro:material_abb_white/>
        <material name="yellow"/>
      </visual>
    </link>
    <link name="${prefix}shoulder_lift_link">
      <collision name="collision">
        <geometry>
          <mesh filename="package://irb4600_description/meshes/collision/link_2.stl"/>
        </geometry>
        <xacro:material_abb_white/>
      </collision>
      <visual name="visual">
        <geometry>
          <mesh filename="package://irb4600_description/meshes/visual/link_2.dae"/>
        </geometry>
        <xacro:material_abb_white/>
        <material name="yellow"/>
      </visual>
    </link>
    <link name="${prefix}elbow_link">
      <collision name="collision">
        <geometry>
          <mesh filename="package://irb4600_description/meshes/collision/link_3.stl"/>
        </geometry>
        <xacro:material_abb_white/>
      </collision>
      <visual name="visual">
        <geometry>
          <mesh filename="package://irb4600_description/meshes/visual/link_3.dae"/>
        </geometry>
        <xacro:material_abb_white/>
        <material name="yellow"/>
      </visual>
    </link>
    <link name="${prefix}wrist_1_link">
      <collision name="collision">
        <geometry>
          <mesh filename="package://irb4600_description/meshes/collision/link_4.stl"/>
        </geometry>
        <xacro:material_abb_white/>
      </collision>
      <visual name="visual">
        <geometry>
          <mesh filename="package://irb4600_description/meshes/visual/link_4.dae"/>
        </geometry>
        <xacro:material_abb_white/>
        <material name="yellow"/>
      </visual>
    </link>
    <link name="${prefix}wrist_2_link">
      <collision name="collision">
        <geometry>
          <mesh filename="package://irb4600_description/meshes/collision/link_5.stl"/>
        </geometry>
        <xacro:material_abb_white/>
      </collision>
      <visual name="visual">
        <geometry>
          <mesh filename="package://irb4600_description/meshes/visual/link_5.dae"/>
        </geometry>
        <xacro:material_abb_white/>
        <material name="yellow"/>
      </visual>
    </link>
    <link name="${prefix}wrist_3_link">
      <collision name="collision">
        <geometry>
          <mesh filename="package://irb4600_description/meshes/collision/link_6.stl"/>
        </geometry>
        <xacro:material_abb_white/>
      </collision>
      <visual name="visual">
        <geometry>
          <mesh filename="package://irb4600_description/meshes/visual/link_6.dae"/>
        </geometry>
        <xacro:material_abb_white/>
        <material name="yellow"/>
      </visual>
    </link>
    <!-- end of link list -->

    <!-- joint list -->
    <joint type="revolute" name="${prefix}shoulder_pan_joint">
      <origin xyz="0 0 0.495" rpy="0 0 0"/>
      <axis xyz="0 0 1"/>
      <parent link="${prefix}base_link"/>
      <child link="${prefix}shoulder_pan_link"/>
      <limit effort="0" lower="${radians(-180)}" upper="${radians(180)}" velocity="${radians(175)}"/>
    </joint>
    <joint type="revolute" name="${prefix}shoulder_lift_joint">
      <origin xyz="0.175 0 0" rpy="0 0 0"/>
      <axis xyz="0 1 0"/>
      <parent link="${prefix}shoulder_pan_link"/>
      <child link="${prefix}shoulder_lift_link"/>
      <limit effort="0" lower="${radians(-90)}" upper="${radians(150)}" velocity="${radians(175)}"/>
    </joint>
    <joint type="revolute" name="${prefix}elbow_joint">
      <origin xyz="0 0 1.095" rpy="0 0 0"/>
      <axis xyz="0 1 0"/>
      <parent link="${prefix}shoulder_lift_link"/>
      <child link="${prefix}elbow_link"/>
      <limit effort="0" lower="${radians(-180)}" upper="${radians(75)}" velocity="${radians(175)}"/>
    </joint>
    <joint type="revolute" name="${prefix}wrist_1_joint">
      <origin xyz="0 0 0.175" rpy="0 0 0"/>
      <axis xyz="1 0 0"/>
      <parent link="${prefix}elbow_link"/>
      <child link="${prefix}wrist_1_link"/>
      <limit effort="0" lower="${radians(-400)}" upper="${radians(400)}" velocity="${radians(250)}"/>
    </joint>
    <joint type="revolute" name="${prefix}wrist_2_joint">
      <origin xyz="1.270 0 0" rpy="0 0 0"/>
      <axis xyz="0 1 0"/>
      <parent link="${prefix}wrist_1_link"/>
      <child link="${prefix}wrist_2_link"/>
      <limit effort="0" lower="${radians(-125)}" upper="${radians(120)}" velocity="${radians(250)}"/>
    </joint>
    <joint type="revolute" name="${prefix}wrist_3_joint">
      <origin xyz="0.135 0 0" rpy="0 0 0"/>
      <axis xyz="1 0 0"/>
      <parent link="${prefix}wrist_2_link"/>
      <child link="${prefix}wrist_3_link"/>
      <limit effort="0" lower="${radians(-400)}" upper="${radians(400)}" velocity="${radians(360)}"/>
    </joint>
    <!-- end of joint list -->

    <!-- ROS-Industrial 'base' frame: base_link to ABB World Coordinates transform -->
    <link name="${prefix}base" />
    <joint name="${prefix}base_link-base" type="fixed">
      <origin xyz="0 0 0" rpy="0 0 0"/>
      <parent link="${prefix}base_link"/>
      <child link="${prefix}base"/>
    </joint>

    <!-- ROS-Industrial 'flange' frame: attachment point for EEF models -->
    <link name="${prefix}flange"/>
    <joint type="fixed" name="${prefix}joint_6-flange">
      <origin xyz="0 0 0" rpy="0 0 0"/>
      <parent link="${prefix}wrist_3_link"/>
      <child link="${prefix}flange"/>
    </joint>

    <!-- ROS-Industrial 'tool0' frame: all-zeros tool frame -->
    <link name="${prefix}tools" />
    <joint name="${prefix}wrist_3_link-tool" type="fixed">
      <origin xyz="0 0 0" rpy="0 ${radians(90)} 0" />
      <parent link="${prefix}flange" />
      <child link="${prefix}tools" />
    </joint>
  </xacro:macro>
</robot>
