#VRML_SIM R2022a utf8
WorldInfo {
}
Viewpoint {
  orientation -0.41056890902974785 -0.1780342762645949 0.8942801392254356 3.881463879890889
  position 0.21045596102515154 0.2863703568747492 0.44512689752680745
}
TexturedBackground {
}
TexturedBackgroundLight {
}
Floor {
}
Robot {
  controller "<extern>"
  rotation 0 1 0 -1.57
  children [
    DEF LIFT_SLIDER SliderJoint {
      jointParameters JointParameters {
        axis 0 0 -1
      }
      device [
        LinearMotor {
          name "lift motor"
          minPosition -0.05
          maxPosition 0.05
        }
      ]
      endPoint DEF LIFT Solid {
        translation 0.0425 0 0
        rotation 0.5773502691896258 -0.5773502691896258 -0.5773502691896258 2.094395
        children [
          DEF LEFT_FINGER_SLIDER SliderJoint {
            jointParameters JointParameters {
              axis -1 0 0
            }
             device [
               LinearMotor {
                 name "left_finger_joint"
                 maxPosition 0.12
                 maxForce 300
               }
               PositionSensor {
                 name "left_finger_joint_sensor"
               }
             ]
            endPoint DEF LEFT_FINGER Solid {
              translation -0.022 0 -0.02
              children [
                Group {
                  children [
                    Transform {
                      translation 0 0.0015 -0.003
                      children [
                        Shape {
                          appearance DEF METAL_APPEARANCE PBRAppearance {
                            baseColorMap ImageTexture {
                              url [
                                "https://raw.githubusercontent.com/cyberbotics/webots/R2022a/projects/default/worlds/textures/metal.jpg"
                              ]
                            }
                            roughness 0.2
                          }
                          geometry Box {
                            size 0.018 0.031 0.036
                          }
                        }
                      ]
                    }
                    DEF LEFT_FINGER_TRANSFORM Transform {
                      translation 0 -0.002 -0.069
                      children [
                        Shape {
                          appearance DEF BLACK_APPEARANCE PBRAppearance {
                            baseColor 0.0705882 0.0705882 0.0705882
                            roughness 0.4
                            metalness 0
                          }
                          geometry Box {
                            size 0.018 0.031 0.095
                          }
                        }
                      ]
                    }
                  ]
                }
              ]
              name "left finger"
              boundingObject USE LEFT_FINGER_TRANSFORM
              physics DEF LEFT_FINGER_PHYSICS Physics {
              }
            }
          }
          DEF RIGHT_FINGER_SLIDER SliderJoint {
            jointParameters JointParameters {
              axis 1 0 0
            }
            device [
                LinearMotor {
                  name "right_finger_joint"
                  maxPosition 0.12
                  maxForce 300
                }
                PositionSensor {
                  name "right_finger_joint_sensor"
                }
                  ]
            endPoint DEF RIGHT_FINGER Solid {
              translation 0.021 0 -0.02
              children [
                Group {
                  children [
                    Transform {
                      translation 0 0.0015 -0.003
                      children [
                        Shape {
                          appearance USE METAL_APPEARANCE
                          geometry Box {
                            size 0.018 0.031 0.036
                          }
                        }
                      ]
                    }
                    DEF RIGHT_FINGER_TRANSFORM Transform {
                      translation 0 -0.002 -0.069
                      children [
                        Shape {
                          appearance USE BLACK_APPEARANCE
                          geometry Box {
                            size 0.018 0.031 0.095
                          }
                        }
                      ]
                    }
                  ]
                }
              ]
              name "right finger"
              boundingObject USE RIGHT_FINGER_TRANSFORM
              physics USE LEFT_FINGER_PHYSICS
            }
          }
          Transform {
            translation 0 -0.126 0.135
            children [
              Group {
                children [
                  Transform {
                    translation 0 0.1478 -0.154
                    children [
                      DEF UPPER_BOX Shape {
                        appearance USE BLACK_APPEARANCE
                        geometry Box {
                          size 0.315 0.01 0.043419
                        }
                      }
                    ]
                  }
                  Transform {
                    translation 0 0.1072 -0.154
                    children [
                      USE UPPER_BOX
                    ]
                  }
                  Transform {
                    translation -0.155 0.1275 -0.154
                    children [
                      DEF LEFT_BOX Shape {
                        appearance USE BLACK_APPEARANCE
                        geometry Box {
                          size 0.007 0.05 0.042227
                        }
                      }
                    ]
                  }
                  Transform {
                    translation 0.155 0.1275 -0.154
                    children [
                      USE LEFT_BOX
                    ]
                  }
                  Transform {
                    translation 0 0.126 -0.158
                    children [
                      DEF CENTER_BOX Shape {
                        appearance USE BLACK_APPEARANCE
                        geometry Box {
                          size 0.027 0.0341 0.035
                        }
                      }
                    ]
                  }
                ]
              }
            ]
          }
        ]
        boundingObject Transform {
          translation 0 0.0015 -0.019
          children [
            Shape {
              appearance USE METAL_APPEARANCE
              geometry Box {
                size 0.315 0.05 0.045
              }
            }
          ]
        }
        physics DEF LIFT_PHYSICS Physics {
        }
      }
    }
  ]
  name "Pioneer3 gripper"
  model "Pioneer3 gripper"
  boundingObject Transform {
    translation 0.019 0 0
    children [
      Box {
        size 0.043 0.141 0.117
      }
    ]
  }
  physics DEF BASE_PHYSICS Physics {
  }
}
