<?xml version="1.0"?>
<robot xmlns:xacro="http://ros.org/wiki/xacro">
    <xacro:macro name="gripper" params="prefix">
        <!-- link list -->
        <link name="${prefix}palm_link">
            <collision name="collision">
                <geometry>
                    <mesh filename="package://gripper_description/meshes/collision/gripper_base.stl"/>
                </geometry>
            </collision>
            <visual name="visual">
                <geometry>
                    <mesh filename="package://gripper_description/meshes/visual/gripper_base.dae"/>
                </geometry>
            </visual>
        </link>
        <link name="${prefix}left_finger">
            <collision name="collision">
                <geometry>
                    <mesh filename="package://gripper_description/meshes/collision/left_finger.stl"/>
                </geometry>
            </collision>
            <visual name="visual">
                <geometry>
                    <mesh filename="package://gripper_description/meshes/visual/left_finger.dae"/>
                </geometry>
            </visual>
        </link>
        <link name="${prefix}right_finger">
            <collision name="collision">
                <geometry>
                    <mesh filename="package://gripper_description/meshes/collision/right_finger.stl"/>
                </geometry>
            </collision>
            <visual name="visual">
                <geometry>
                    <mesh filename="package://gripper_description/meshes/visual/right_finger.dae"/>
                </geometry>
            </visual>
        </link>

        <!-- joint list -->
        <joint type="prismatic" name="${prefix}left_finger_joint">
            <origin xyz="0 0 0" rpy="0 0 0"/>
            <axis xyz="-1 0 0"/>
            <parent link="${prefix}palm_link"/>
            <child link="${prefix}left_finger"/>
            <limit effort="300" lower="0" upper="0.12" velocity="10"/>
        </joint>
        <joint type="prismatic" name="${prefix}right_finger_joint">
            <origin xyz="0 0 0" rpy="0 0 0"/>
            <axis xyz="1 0 0"/>
            <parent link="${prefix}palm_link"/>
            <child link="${prefix}right_finger"/>
            <limit effort="300" lower="0" upper="0.12" velocity="10"/>
        </joint>

    </xacro:macro>
</robot>
